[2024-09-24T19:15:54.933+0000] {local_task_job_runner.py:123} INFO - ::group::Pre task execution logs
[2024-09-24T19:15:54.955+0000] {taskinstance.py:2612} INFO - Dependencies all met for dep_context=non-requeueable deps ti=<TaskInstance: dag1.1.task1 scheduled__2024-09-23T01:49:00+00:00 [queued]>
[2024-09-24T19:15:54.968+0000] {taskinstance.py:2612} INFO - Dependencies all met for dep_context=requeueable deps ti=<TaskInstance: dag1.1.task1 scheduled__2024-09-23T01:49:00+00:00 [queued]>
[2024-09-24T19:15:54.970+0000] {taskinstance.py:2865} INFO - Starting attempt 4 of 4
[2024-09-24T19:15:54.992+0000] {taskinstance.py:2888} INFO - Executing <Task(BashOperator): task1> on 2024-09-23 01:49:00+00:00
[2024-09-24T19:15:55.008+0000] {warnings.py:112} WARNING - /home/***/.local/lib/python3.12/site-packages/***/task/task_runner/standard_task_runner.py:70: DeprecationWarning: This process (pid=140) is multi-threaded, use of fork() may lead to deadlocks in the child.
  pid = os.fork()

[2024-09-24T19:15:55.010+0000] {standard_task_runner.py:104} INFO - Running: ['***', 'tasks', 'run', 'dag1.1', 'task1', 'scheduled__2024-09-23T01:49:00+00:00', '--job-id', '598', '--raw', '--subdir', 'DAGS_FOLDER/dag1.1.py', '--cfg-path', '/tmp/tmpgwkwjjex']
[2024-09-24T19:15:55.014+0000] {standard_task_runner.py:72} INFO - Started process 141 to run task
[2024-09-24T19:15:55.022+0000] {standard_task_runner.py:105} INFO - Job 598: Subtask task1
[2024-09-24T19:15:55.081+0000] {task_command.py:467} INFO - Running <TaskInstance: dag1.1.task1 scheduled__2024-09-23T01:49:00+00:00 [running]> on host 9931046d9fab
[2024-09-24T19:15:55.167+0000] {taskinstance.py:3131} INFO - Exporting env vars: AIRFLOW_CTX_DAG_OWNER='etl_user' AIRFLOW_CTX_DAG_ID='dag1.1' AIRFLOW_CTX_TASK_ID='task1' AIRFLOW_CTX_EXECUTION_DATE='2024-09-23T01:49:00+00:00' AIRFLOW_CTX_TRY_NUMBER='4' AIRFLOW_CTX_DAG_RUN_ID='scheduled__2024-09-23T01:49:00+00:00'
[2024-09-24T19:15:55.168+0000] {taskinstance.py:731} INFO - ::endgroup::
[2024-09-24T19:15:55.190+0000] {subprocess.py:63} INFO - Tmp dir root location: /tmp
[2024-09-24T19:15:55.192+0000] {subprocess.py:75} INFO - Running command: ['/usr/bin/bash', '-c', 'python3 /opt/***/***_project/scripts/dag1.1/task1.py']
[2024-09-24T19:15:55.208+0000] {subprocess.py:86} INFO - Output:
[2024-09-24T19:15:55.246+0000] {subprocess.py:93} INFO - python3: can't open file '/opt/***/***_project/scripts/dag1.1/task1.py': [Errno 2] No such file or directory
[2024-09-24T19:15:55.249+0000] {subprocess.py:97} INFO - Command exited with return code 2
[2024-09-24T19:15:55.263+0000] {taskinstance.py:3310} ERROR - Task failed with exception
Traceback (most recent call last):
  File "/home/airflow/.local/lib/python3.12/site-packages/airflow/models/taskinstance.py", line 767, in _execute_task
    result = _execute_callable(context=context, **execute_callable_kwargs)
             ^^^^^^^^^^^^^^^^^^^^^^^^^^^^^^^^^^^^^^^^^^^^^^^^^^^^^^^^^^^^^
  File "/home/airflow/.local/lib/python3.12/site-packages/airflow/models/taskinstance.py", line 733, in _execute_callable
    return ExecutionCallableRunner(
           ^^^^^^^^^^^^^^^^^^^^^^^^
  File "/home/airflow/.local/lib/python3.12/site-packages/airflow/utils/operator_helpers.py", line 252, in run
    return self.func(*args, **kwargs)
           ^^^^^^^^^^^^^^^^^^^^^^^^^^
  File "/home/airflow/.local/lib/python3.12/site-packages/airflow/models/baseoperator.py", line 406, in wrapper
    return func(self, *args, **kwargs)
           ^^^^^^^^^^^^^^^^^^^^^^^^^^^
  File "/home/airflow/.local/lib/python3.12/site-packages/airflow/operators/bash.py", line 249, in execute
    raise AirflowException(
airflow.exceptions.AirflowException: Bash command failed. The command returned a non-zero exit code 2.
[2024-09-24T19:15:55.269+0000] {taskinstance.py:1225} INFO - Marking task as FAILED. dag_id=dag1.1, task_id=task1, run_id=scheduled__2024-09-23T01:49:00+00:00, execution_date=20240923T014900, start_date=20240924T191554, end_date=20240924T191555
[2024-09-24T19:15:55.284+0000] {taskinstance.py:340} INFO - ::group::Post task execution logs
[2024-09-24T19:15:55.285+0000] {standard_task_runner.py:124} ERROR - Failed to execute job 598 for task task1 (Bash command failed. The command returned a non-zero exit code 2.; 141)
Traceback (most recent call last):
  File "/home/airflow/.local/lib/python3.12/site-packages/airflow/task/task_runner/standard_task_runner.py", line 117, in _start_by_fork
    ret = args.func(args, dag=self.dag)
          ^^^^^^^^^^^^^^^^^^^^^^^^^^^^^
  File "/home/airflow/.local/lib/python3.12/site-packages/airflow/cli/cli_config.py", line 49, in command
    return func(*args, **kwargs)
           ^^^^^^^^^^^^^^^^^^^^^
  File "/home/airflow/.local/lib/python3.12/site-packages/airflow/utils/cli.py", line 115, in wrapper
    return f(*args, **kwargs)
           ^^^^^^^^^^^^^^^^^^
  File "/home/airflow/.local/lib/python3.12/site-packages/airflow/cli/commands/task_command.py", line 483, in task_run
    task_return_code = _run_task_by_selected_method(args, _dag, ti)
                       ^^^^^^^^^^^^^^^^^^^^^^^^^^^^^^^^^^^^^^^^^^^^
  File "/home/airflow/.local/lib/python3.12/site-packages/airflow/cli/commands/task_command.py", line 256, in _run_task_by_selected_method
    return _run_raw_task(args, ti)
           ^^^^^^^^^^^^^^^^^^^^^^^
  File "/home/airflow/.local/lib/python3.12/site-packages/airflow/cli/commands/task_command.py", line 341, in _run_raw_task
    return ti._run_raw_task(
           ^^^^^^^^^^^^^^^^^
  File "/home/airflow/.local/lib/python3.12/site-packages/airflow/utils/session.py", line 97, in wrapper
    return func(*args, session=session, **kwargs)
           ^^^^^^^^^^^^^^^^^^^^^^^^^^^^^^^^^^^^^^
  File "/home/airflow/.local/lib/python3.12/site-packages/airflow/models/taskinstance.py", line 3004, in _run_raw_task
    return _run_raw_task(
           ^^^^^^^^^^^^^^
  File "/home/airflow/.local/lib/python3.12/site-packages/airflow/models/taskinstance.py", line 273, in _run_raw_task
    TaskInstance._execute_task_with_callbacks(
  File "/home/airflow/.local/lib/python3.12/site-packages/airflow/models/taskinstance.py", line 3158, in _execute_task_with_callbacks
    result = self._execute_task(context, task_orig)
             ^^^^^^^^^^^^^^^^^^^^^^^^^^^^^^^^^^^^^^
  File "/home/airflow/.local/lib/python3.12/site-packages/airflow/models/taskinstance.py", line 3182, in _execute_task
    return _execute_task(self, context, task_orig)
           ^^^^^^^^^^^^^^^^^^^^^^^^^^^^^^^^^^^^^^^
  File "/home/airflow/.local/lib/python3.12/site-packages/airflow/models/taskinstance.py", line 767, in _execute_task
    result = _execute_callable(context=context, **execute_callable_kwargs)
             ^^^^^^^^^^^^^^^^^^^^^^^^^^^^^^^^^^^^^^^^^^^^^^^^^^^^^^^^^^^^^
  File "/home/airflow/.local/lib/python3.12/site-packages/airflow/models/taskinstance.py", line 733, in _execute_callable
    return ExecutionCallableRunner(
           ^^^^^^^^^^^^^^^^^^^^^^^^
  File "/home/airflow/.local/lib/python3.12/site-packages/airflow/utils/operator_helpers.py", line 252, in run
    return self.func(*args, **kwargs)
           ^^^^^^^^^^^^^^^^^^^^^^^^^^
  File "/home/airflow/.local/lib/python3.12/site-packages/airflow/models/baseoperator.py", line 406, in wrapper
    return func(self, *args, **kwargs)
           ^^^^^^^^^^^^^^^^^^^^^^^^^^^
  File "/home/airflow/.local/lib/python3.12/site-packages/airflow/operators/bash.py", line 249, in execute
    raise AirflowException(
airflow.exceptions.AirflowException: Bash command failed. The command returned a non-zero exit code 2.
[2024-09-24T19:15:55.319+0000] {local_task_job_runner.py:266} INFO - Task exited with return code 1
[2024-09-24T19:15:55.344+0000] {taskinstance.py:3900} INFO - 0 downstream tasks scheduled from follow-on schedule check
[2024-09-24T19:15:55.350+0000] {local_task_job_runner.py:245} INFO - ::endgroup::
