[2024-09-22T16:22:56.259+0000] {local_task_job_runner.py:123} INFO - ::group::Pre task execution logs
[2024-09-22T16:22:56.293+0000] {taskinstance.py:2612} INFO - Dependencies all met for dep_context=non-requeueable deps ti=<TaskInstance: dag1.1.task1 manual__2024-09-22T16:09:14.628803+00:00 [queued]>
[2024-09-22T16:22:56.310+0000] {taskinstance.py:2612} INFO - Dependencies all met for dep_context=requeueable deps ti=<TaskInstance: dag1.1.task1 manual__2024-09-22T16:09:14.628803+00:00 [queued]>
[2024-09-22T16:22:56.311+0000] {taskinstance.py:2865} INFO - Starting attempt 1 of 4
[2024-09-22T16:22:56.332+0000] {taskinstance.py:2888} INFO - Executing <Task(BashOperator): task1> on 2024-09-22 16:09:14.628803+00:00
[2024-09-22T16:22:56.347+0000] {warnings.py:112} WARNING - /home/***/.local/lib/python3.12/site-packages/***/task/task_runner/standard_task_runner.py:70: DeprecationWarning: This process (pid=62) is multi-threaded, use of fork() may lead to deadlocks in the child.
  pid = os.fork()

[2024-09-22T16:22:56.359+0000] {standard_task_runner.py:72} INFO - Started process 63 to run task
[2024-09-22T16:22:56.359+0000] {standard_task_runner.py:104} INFO - Running: ['***', 'tasks', 'run', 'dag1.1', 'task1', 'manual__2024-09-22T16:09:14.628803+00:00', '--job-id', '50', '--raw', '--subdir', 'DAGS_FOLDER/dag1.1.py', '--cfg-path', '/tmp/tmpo1nyyr69']
[2024-09-22T16:22:56.364+0000] {standard_task_runner.py:105} INFO - Job 50: Subtask task1
[2024-09-22T16:22:56.567+0000] {task_command.py:467} INFO - Running <TaskInstance: dag1.1.task1 manual__2024-09-22T16:09:14.628803+00:00 [running]> on host 840529986b74
[2024-09-22T16:22:56.821+0000] {taskinstance.py:3131} INFO - Exporting env vars: AIRFLOW_CTX_DAG_OWNER='etl_user' AIRFLOW_CTX_DAG_ID='dag1.1' AIRFLOW_CTX_TASK_ID='task1' AIRFLOW_CTX_EXECUTION_DATE='2024-09-22T16:09:14.628803+00:00' AIRFLOW_CTX_TRY_NUMBER='1' AIRFLOW_CTX_DAG_RUN_ID='manual__2024-09-22T16:09:14.628803+00:00'
[2024-09-22T16:22:56.828+0000] {taskinstance.py:731} INFO - ::endgroup::
[2024-09-22T16:22:57.149+0000] {subprocess.py:63} INFO - Tmp dir root location: /tmp
[2024-09-22T16:22:57.150+0000] {subprocess.py:75} INFO - Running command: ['/usr/bin/bash', '-c', 'scripts/dag1.1/task1.py']
[2024-09-22T16:22:57.172+0000] {subprocess.py:86} INFO - Output:
[2024-09-22T16:22:57.184+0000] {subprocess.py:93} INFO - /usr/bin/bash: line 1: scripts/dag1.1/task1.py: No such file or directory
[2024-09-22T16:22:57.185+0000] {subprocess.py:97} INFO - Command exited with return code 127
[2024-09-22T16:22:57.205+0000] {taskinstance.py:3310} ERROR - Task failed with exception
Traceback (most recent call last):
  File "/home/airflow/.local/lib/python3.12/site-packages/airflow/models/taskinstance.py", line 767, in _execute_task
    result = _execute_callable(context=context, **execute_callable_kwargs)
             ^^^^^^^^^^^^^^^^^^^^^^^^^^^^^^^^^^^^^^^^^^^^^^^^^^^^^^^^^^^^^
  File "/home/airflow/.local/lib/python3.12/site-packages/airflow/models/taskinstance.py", line 733, in _execute_callable
    return ExecutionCallableRunner(
           ^^^^^^^^^^^^^^^^^^^^^^^^
  File "/home/airflow/.local/lib/python3.12/site-packages/airflow/utils/operator_helpers.py", line 252, in run
    return self.func(*args, **kwargs)
           ^^^^^^^^^^^^^^^^^^^^^^^^^^
  File "/home/airflow/.local/lib/python3.12/site-packages/airflow/models/baseoperator.py", line 406, in wrapper
    return func(self, *args, **kwargs)
           ^^^^^^^^^^^^^^^^^^^^^^^^^^^
  File "/home/airflow/.local/lib/python3.12/site-packages/airflow/operators/bash.py", line 249, in execute
    raise AirflowException(
airflow.exceptions.AirflowException: Bash command failed. The command returned a non-zero exit code 127.
[2024-09-22T16:22:57.241+0000] {taskinstance.py:1225} INFO - Marking task as UP_FOR_RETRY. dag_id=dag1.1, task_id=task1, run_id=manual__2024-09-22T16:09:14.628803+00:00, execution_date=20240922T160914, start_date=20240922T162256, end_date=20240922T162257
[2024-09-22T16:22:57.276+0000] {taskinstance.py:340} INFO - ::group::Post task execution logs
[2024-09-22T16:22:57.277+0000] {standard_task_runner.py:124} ERROR - Failed to execute job 50 for task task1 (Bash command failed. The command returned a non-zero exit code 127.; 63)
Traceback (most recent call last):
  File "/home/airflow/.local/lib/python3.12/site-packages/airflow/task/task_runner/standard_task_runner.py", line 117, in _start_by_fork
    ret = args.func(args, dag=self.dag)
          ^^^^^^^^^^^^^^^^^^^^^^^^^^^^^
  File "/home/airflow/.local/lib/python3.12/site-packages/airflow/cli/cli_config.py", line 49, in command
    return func(*args, **kwargs)
           ^^^^^^^^^^^^^^^^^^^^^
  File "/home/airflow/.local/lib/python3.12/site-packages/airflow/utils/cli.py", line 115, in wrapper
    return f(*args, **kwargs)
           ^^^^^^^^^^^^^^^^^^
  File "/home/airflow/.local/lib/python3.12/site-packages/airflow/cli/commands/task_command.py", line 483, in task_run
    task_return_code = _run_task_by_selected_method(args, _dag, ti)
                       ^^^^^^^^^^^^^^^^^^^^^^^^^^^^^^^^^^^^^^^^^^^^
  File "/home/airflow/.local/lib/python3.12/site-packages/airflow/cli/commands/task_command.py", line 256, in _run_task_by_selected_method
    return _run_raw_task(args, ti)
           ^^^^^^^^^^^^^^^^^^^^^^^
  File "/home/airflow/.local/lib/python3.12/site-packages/airflow/cli/commands/task_command.py", line 341, in _run_raw_task
    return ti._run_raw_task(
           ^^^^^^^^^^^^^^^^^
  File "/home/airflow/.local/lib/python3.12/site-packages/airflow/utils/session.py", line 97, in wrapper
    return func(*args, session=session, **kwargs)
           ^^^^^^^^^^^^^^^^^^^^^^^^^^^^^^^^^^^^^^
  File "/home/airflow/.local/lib/python3.12/site-packages/airflow/models/taskinstance.py", line 3004, in _run_raw_task
    return _run_raw_task(
           ^^^^^^^^^^^^^^
  File "/home/airflow/.local/lib/python3.12/site-packages/airflow/models/taskinstance.py", line 273, in _run_raw_task
    TaskInstance._execute_task_with_callbacks(
  File "/home/airflow/.local/lib/python3.12/site-packages/airflow/models/taskinstance.py", line 3158, in _execute_task_with_callbacks
    result = self._execute_task(context, task_orig)
             ^^^^^^^^^^^^^^^^^^^^^^^^^^^^^^^^^^^^^^
  File "/home/airflow/.local/lib/python3.12/site-packages/airflow/models/taskinstance.py", line 3182, in _execute_task
    return _execute_task(self, context, task_orig)
           ^^^^^^^^^^^^^^^^^^^^^^^^^^^^^^^^^^^^^^^
  File "/home/airflow/.local/lib/python3.12/site-packages/airflow/models/taskinstance.py", line 767, in _execute_task
    result = _execute_callable(context=context, **execute_callable_kwargs)
             ^^^^^^^^^^^^^^^^^^^^^^^^^^^^^^^^^^^^^^^^^^^^^^^^^^^^^^^^^^^^^
  File "/home/airflow/.local/lib/python3.12/site-packages/airflow/models/taskinstance.py", line 733, in _execute_callable
    return ExecutionCallableRunner(
           ^^^^^^^^^^^^^^^^^^^^^^^^
  File "/home/airflow/.local/lib/python3.12/site-packages/airflow/utils/operator_helpers.py", line 252, in run
    return self.func(*args, **kwargs)
           ^^^^^^^^^^^^^^^^^^^^^^^^^^
  File "/home/airflow/.local/lib/python3.12/site-packages/airflow/models/baseoperator.py", line 406, in wrapper
    return func(self, *args, **kwargs)
           ^^^^^^^^^^^^^^^^^^^^^^^^^^^
  File "/home/airflow/.local/lib/python3.12/site-packages/airflow/operators/bash.py", line 249, in execute
    raise AirflowException(
airflow.exceptions.AirflowException: Bash command failed. The command returned a non-zero exit code 127.
[2024-09-22T16:22:57.334+0000] {local_task_job_runner.py:266} INFO - Task exited with return code 1
[2024-09-22T16:22:57.363+0000] {taskinstance.py:3900} INFO - 0 downstream tasks scheduled from follow-on schedule check
[2024-09-22T16:22:57.366+0000] {local_task_job_runner.py:245} INFO - ::endgroup::
