[2024-09-24T18:37:35.772+0000] {local_task_job_runner.py:123} INFO - ::group::Pre task execution logs
[2024-09-24T18:37:35.801+0000] {taskinstance.py:2612} INFO - Dependencies all met for dep_context=non-requeueable deps ti=<TaskInstance: dag1.task1 scheduled__2024-09-24T00:00:00+00:00 [queued]>
[2024-09-24T18:37:35.815+0000] {taskinstance.py:2612} INFO - Dependencies all met for dep_context=requeueable deps ti=<TaskInstance: dag1.task1 scheduled__2024-09-24T00:00:00+00:00 [queued]>
[2024-09-24T18:37:35.816+0000] {taskinstance.py:2865} INFO - Starting attempt 4 of 4
[2024-09-24T18:37:35.840+0000] {taskinstance.py:2888} INFO - Executing <Task(BashOperator): task1> on 2024-09-24 00:00:00+00:00
[2024-09-24T18:37:35.848+0000] {warnings.py:112} WARNING - /home/***/.local/lib/python3.12/site-packages/***/task/task_runner/standard_task_runner.py:70: DeprecationWarning: This process (pid=135) is multi-threaded, use of fork() may lead to deadlocks in the child.
  pid = os.fork()

[2024-09-24T18:37:35.849+0000] {standard_task_runner.py:104} INFO - Running: ['***', 'tasks', 'run', 'dag1', 'task1', 'scheduled__2024-09-24T00:00:00+00:00', '--job-id', '530', '--raw', '--subdir', 'DAGS_FOLDER/dag1.py', '--cfg-path', '/tmp/tmptzsquaed']
[2024-09-24T18:37:35.851+0000] {standard_task_runner.py:72} INFO - Started process 136 to run task
[2024-09-24T18:37:35.852+0000] {standard_task_runner.py:105} INFO - Job 530: Subtask task1
[2024-09-24T18:37:35.909+0000] {task_command.py:467} INFO - Running <TaskInstance: dag1.task1 scheduled__2024-09-24T00:00:00+00:00 [running]> on host 1ea3ed4afb09
[2024-09-24T18:37:36.010+0000] {taskinstance.py:3131} INFO - Exporting env vars: AIRFLOW_CTX_DAG_OWNER='etl_user' AIRFLOW_CTX_DAG_ID='dag1' AIRFLOW_CTX_TASK_ID='task1' AIRFLOW_CTX_EXECUTION_DATE='2024-09-24T00:00:00+00:00' AIRFLOW_CTX_TRY_NUMBER='4' AIRFLOW_CTX_DAG_RUN_ID='scheduled__2024-09-24T00:00:00+00:00'
[2024-09-24T18:37:36.012+0000] {taskinstance.py:731} INFO - ::endgroup::
[2024-09-24T18:37:36.052+0000] {subprocess.py:63} INFO - Tmp dir root location: /tmp
[2024-09-24T18:37:36.060+0000] {subprocess.py:75} INFO - Running command: ['/usr/bin/bash', '-c', 'scripts/dag1/task1.py']
[2024-09-24T18:37:36.077+0000] {subprocess.py:86} INFO - Output:
[2024-09-24T18:37:36.095+0000] {subprocess.py:93} INFO - /usr/bin/bash: line 1: scripts/dag1/task1.py: No such file or directory
[2024-09-24T18:37:36.097+0000] {subprocess.py:97} INFO - Command exited with return code 127
[2024-09-24T18:37:36.111+0000] {taskinstance.py:3310} ERROR - Task failed with exception
Traceback (most recent call last):
  File "/home/airflow/.local/lib/python3.12/site-packages/airflow/models/taskinstance.py", line 767, in _execute_task
    result = _execute_callable(context=context, **execute_callable_kwargs)
             ^^^^^^^^^^^^^^^^^^^^^^^^^^^^^^^^^^^^^^^^^^^^^^^^^^^^^^^^^^^^^
  File "/home/airflow/.local/lib/python3.12/site-packages/airflow/models/taskinstance.py", line 733, in _execute_callable
    return ExecutionCallableRunner(
           ^^^^^^^^^^^^^^^^^^^^^^^^
  File "/home/airflow/.local/lib/python3.12/site-packages/airflow/utils/operator_helpers.py", line 252, in run
    return self.func(*args, **kwargs)
           ^^^^^^^^^^^^^^^^^^^^^^^^^^
  File "/home/airflow/.local/lib/python3.12/site-packages/airflow/models/baseoperator.py", line 406, in wrapper
    return func(self, *args, **kwargs)
           ^^^^^^^^^^^^^^^^^^^^^^^^^^^
  File "/home/airflow/.local/lib/python3.12/site-packages/airflow/operators/bash.py", line 249, in execute
    raise AirflowException(
airflow.exceptions.AirflowException: Bash command failed. The command returned a non-zero exit code 127.
[2024-09-24T18:37:36.119+0000] {taskinstance.py:1225} INFO - Marking task as FAILED. dag_id=dag1, task_id=task1, run_id=scheduled__2024-09-24T00:00:00+00:00, execution_date=20240924T000000, start_date=20240924T183735, end_date=20240924T183736
[2024-09-24T18:37:36.137+0000] {taskinstance.py:340} INFO - ::group::Post task execution logs
[2024-09-24T18:37:36.139+0000] {standard_task_runner.py:124} ERROR - Failed to execute job 530 for task task1 (Bash command failed. The command returned a non-zero exit code 127.; 136)
Traceback (most recent call last):
  File "/home/airflow/.local/lib/python3.12/site-packages/airflow/task/task_runner/standard_task_runner.py", line 117, in _start_by_fork
    ret = args.func(args, dag=self.dag)
          ^^^^^^^^^^^^^^^^^^^^^^^^^^^^^
  File "/home/airflow/.local/lib/python3.12/site-packages/airflow/cli/cli_config.py", line 49, in command
    return func(*args, **kwargs)
           ^^^^^^^^^^^^^^^^^^^^^
  File "/home/airflow/.local/lib/python3.12/site-packages/airflow/utils/cli.py", line 115, in wrapper
    return f(*args, **kwargs)
           ^^^^^^^^^^^^^^^^^^
  File "/home/airflow/.local/lib/python3.12/site-packages/airflow/cli/commands/task_command.py", line 483, in task_run
    task_return_code = _run_task_by_selected_method(args, _dag, ti)
                       ^^^^^^^^^^^^^^^^^^^^^^^^^^^^^^^^^^^^^^^^^^^^
  File "/home/airflow/.local/lib/python3.12/site-packages/airflow/cli/commands/task_command.py", line 256, in _run_task_by_selected_method
    return _run_raw_task(args, ti)
           ^^^^^^^^^^^^^^^^^^^^^^^
  File "/home/airflow/.local/lib/python3.12/site-packages/airflow/cli/commands/task_command.py", line 341, in _run_raw_task
    return ti._run_raw_task(
           ^^^^^^^^^^^^^^^^^
  File "/home/airflow/.local/lib/python3.12/site-packages/airflow/utils/session.py", line 97, in wrapper
    return func(*args, session=session, **kwargs)
           ^^^^^^^^^^^^^^^^^^^^^^^^^^^^^^^^^^^^^^
  File "/home/airflow/.local/lib/python3.12/site-packages/airflow/models/taskinstance.py", line 3004, in _run_raw_task
    return _run_raw_task(
           ^^^^^^^^^^^^^^
  File "/home/airflow/.local/lib/python3.12/site-packages/airflow/models/taskinstance.py", line 273, in _run_raw_task
    TaskInstance._execute_task_with_callbacks(
  File "/home/airflow/.local/lib/python3.12/site-packages/airflow/models/taskinstance.py", line 3158, in _execute_task_with_callbacks
    result = self._execute_task(context, task_orig)
             ^^^^^^^^^^^^^^^^^^^^^^^^^^^^^^^^^^^^^^
  File "/home/airflow/.local/lib/python3.12/site-packages/airflow/models/taskinstance.py", line 3182, in _execute_task
    return _execute_task(self, context, task_orig)
           ^^^^^^^^^^^^^^^^^^^^^^^^^^^^^^^^^^^^^^^
  File "/home/airflow/.local/lib/python3.12/site-packages/airflow/models/taskinstance.py", line 767, in _execute_task
    result = _execute_callable(context=context, **execute_callable_kwargs)
             ^^^^^^^^^^^^^^^^^^^^^^^^^^^^^^^^^^^^^^^^^^^^^^^^^^^^^^^^^^^^^
  File "/home/airflow/.local/lib/python3.12/site-packages/airflow/models/taskinstance.py", line 733, in _execute_callable
    return ExecutionCallableRunner(
           ^^^^^^^^^^^^^^^^^^^^^^^^
  File "/home/airflow/.local/lib/python3.12/site-packages/airflow/utils/operator_helpers.py", line 252, in run
    return self.func(*args, **kwargs)
           ^^^^^^^^^^^^^^^^^^^^^^^^^^
  File "/home/airflow/.local/lib/python3.12/site-packages/airflow/models/baseoperator.py", line 406, in wrapper
    return func(self, *args, **kwargs)
           ^^^^^^^^^^^^^^^^^^^^^^^^^^^
  File "/home/airflow/.local/lib/python3.12/site-packages/airflow/operators/bash.py", line 249, in execute
    raise AirflowException(
airflow.exceptions.AirflowException: Bash command failed. The command returned a non-zero exit code 127.
[2024-09-24T18:37:36.194+0000] {local_task_job_runner.py:266} INFO - Task exited with return code 1
[2024-09-24T18:37:36.220+0000] {taskinstance.py:3900} INFO - 0 downstream tasks scheduled from follow-on schedule check
[2024-09-24T18:37:36.227+0000] {local_task_job_runner.py:245} INFO - ::endgroup::
